/home/zilnora/.conda/envs/MASTER_PROJECT_ENV/lib/python3.9/site-packages/metpy/interpolate/one_dimension.py:147: UserWarning: Interpolation point out of data bounds encountered
  warnings.warn('Interpolation point out of data bounds encountered')
/home/zilnora/.conda/envs/MASTER_PROJECT_ENV/lib/python3.9/site-packages/metpy/interpolate/one_dimension.py:147: UserWarning: Interpolation point out of data bounds encountered
  warnings.warn('Interpolation point out of data bounds encountered')
/home/zilnora/.conda/envs/MASTER_PROJECT_ENV/lib/python3.9/site-packages/metpy/interpolate/one_dimension.py:147: UserWarning: Interpolation point out of data bounds encountered
  warnings.warn('Interpolation point out of data bounds encountered')
/home/zilnora/.conda/envs/MASTER_PROJECT_ENV/lib/python3.9/site-packages/metpy/interpolate/one_dimension.py:147: UserWarning: Interpolation point out of data bounds encountered
  warnings.warn('Interpolation point out of data bounds encountered')
/home/zilnora/.conda/envs/MASTER_PROJECT_ENV/lib/python3.9/site-packages/metpy/interpolate/one_dimension.py:147: UserWarning: Interpolation point out of data bounds encountered
  warnings.warn('Interpolation point out of data bounds encountered')
/home/zilnora/.conda/envs/MASTER_PROJECT_ENV/lib/python3.9/site-packages/metpy/interpolate/one_dimension.py:147: UserWarning: Interpolation point out of data bounds encountered
  warnings.warn('Interpolation point out of data bounds encountered')
/home/zilnora/.conda/envs/MASTER_PROJECT_ENV/lib/python3.9/site-packages/metpy/interpolate/one_dimension.py:147: UserWarning: Interpolation point out of data bounds encountered
  warnings.warn('Interpolation point out of data bounds encountered')
/home/zilnora/.conda/envs/MASTER_PROJECT_ENV/lib/python3.9/site-packages/metpy/interpolate/one_dimension.py:147: UserWarning: Interpolation point out of data bounds encountered
  warnings.warn('Interpolation point out of data bounds encountered')
/home/zilnora/.conda/envs/MASTER_PROJECT_ENV/lib/python3.9/site-packages/metpy/interpolate/one_dimension.py:147: UserWarning: Interpolation point out of data bounds encountered
  warnings.warn('Interpolation point out of data bounds encountered')
/home/zilnora/.conda/envs/MASTER_PROJECT_ENV/lib/python3.9/site-packages/metpy/interpolate/one_dimension.py:147: UserWarning: Interpolation point out of data bounds encountered
  warnings.warn('Interpolation point out of data bounds encountered')
/home/zilnora/.conda/envs/MASTER_PROJECT_ENV/lib/python3.9/site-packages/metpy/interpolate/one_dimension.py:147: UserWarning: Interpolation point out of data bounds encountered
  warnings.warn('Interpolation point out of data bounds encountered')
/home/zilnora/.conda/envs/MASTER_PROJECT_ENV/lib/python3.9/site-packages/metpy/interpolate/one_dimension.py:147: UserWarning: Interpolation point out of data bounds encountered
  warnings.warn('Interpolation point out of data bounds encountered')
/home/zilnora/.conda/envs/MASTER_PROJECT_ENV/lib/python3.9/site-packages/metpy/interpolate/one_dimension.py:147: UserWarning: Interpolation point out of data bounds encountered
  warnings.warn('Interpolation point out of data bounds encountered')
/home/zilnora/.conda/envs/MASTER_PROJECT_ENV/lib/python3.9/site-packages/metpy/interpolate/one_dimension.py:147: UserWarning: Interpolation point out of data bounds encountered
  warnings.warn('Interpolation point out of data bounds encountered')
/home/zilnora/.conda/envs/MASTER_PROJECT_ENV/lib/python3.9/site-packages/metpy/interpolate/one_dimension.py:147: UserWarning: Interpolation point out of data bounds encountered
  warnings.warn('Interpolation point out of data bounds encountered')
/home/zilnora/.conda/envs/MASTER_PROJECT_ENV/lib/python3.9/site-packages/metpy/interpolate/one_dimension.py:147: UserWarning: Interpolation point out of data bounds encountered
  warnings.warn('Interpolation point out of data bounds encountered')
/home/zilnora/.conda/envs/MASTER_PROJECT_ENV/lib/python3.9/site-packages/metpy/interpolate/one_dimension.py:147: UserWarning: Interpolation point out of data bounds encountered
  warnings.warn('Interpolation point out of data bounds encountered')
/home/zilnora/.conda/envs/MASTER_PROJECT_ENV/lib/python3.9/site-packages/metpy/interpolate/one_dimension.py:147: UserWarning: Interpolation point out of data bounds encountered
  warnings.warn('Interpolation point out of data bounds encountered')
/home/zilnora/.conda/envs/MASTER_PROJECT_ENV/lib/python3.9/site-packages/metpy/interpolate/one_dimension.py:147: UserWarning: Interpolation point out of data bounds encountered
  warnings.warn('Interpolation point out of data bounds encountered')
/home/zilnora/.conda/envs/MASTER_PROJECT_ENV/lib/python3.9/site-packages/metpy/interpolate/one_dimension.py:147: UserWarning: Interpolation point out of data bounds encountered
  warnings.warn('Interpolation point out of data bounds encountered')
/home/zilnora/.conda/envs/MASTER_PROJECT_ENV/lib/python3.9/site-packages/metpy/interpolate/one_dimension.py:147: UserWarning: Interpolation point out of data bounds encountered
  warnings.warn('Interpolation point out of data bounds encountered')
/home/zilnora/.conda/envs/MASTER_PROJECT_ENV/lib/python3.9/site-packages/metpy/interpolate/one_dimension.py:147: UserWarning: Interpolation point out of data bounds encountered
  warnings.warn('Interpolation point out of data bounds encountered')
/home/zilnora/.conda/envs/MASTER_PROJECT_ENV/lib/python3.9/site-packages/metpy/interpolate/one_dimension.py:147: UserWarning: Interpolation point out of data bounds encountered
  warnings.warn('Interpolation point out of data bounds encountered')
/home/zilnora/.conda/envs/MASTER_PROJECT_ENV/lib/python3.9/site-packages/metpy/interpolate/one_dimension.py:147: UserWarning: Interpolation point out of data bounds encountered
  warnings.warn('Interpolation point out of data bounds encountered')
/home/zilnora/.conda/envs/MASTER_PROJECT_ENV/lib/python3.9/site-packages/metpy/interpolate/one_dimension.py:147: UserWarning: Interpolation point out of data bounds encountered
  warnings.warn('Interpolation point out of data bounds encountered')
/home/zilnora/.conda/envs/MASTER_PROJECT_ENV/lib/python3.9/site-packages/metpy/interpolate/one_dimension.py:147: UserWarning: Interpolation point out of data bounds encountered
  warnings.warn('Interpolation point out of data bounds encountered')
/home/zilnora/.conda/envs/MASTER_PROJECT_ENV/lib/python3.9/site-packages/metpy/interpolate/one_dimension.py:147: UserWarning: Interpolation point out of data bounds encountered
  warnings.warn('Interpolation point out of data bounds encountered')
/home/zilnora/.conda/envs/MASTER_PROJECT_ENV/lib/python3.9/site-packages/metpy/interpolate/one_dimension.py:147: UserWarning: Interpolation point out of data bounds encountered
  warnings.warn('Interpolation point out of data bounds encountered')
/home/zilnora/.conda/envs/MASTER_PROJECT_ENV/lib/python3.9/site-packages/metpy/interpolate/one_dimension.py:147: UserWarning: Interpolation point out of data bounds encountered
  warnings.warn('Interpolation point out of data bounds encountered')
/home/zilnora/.conda/envs/MASTER_PROJECT_ENV/lib/python3.9/site-packages/metpy/interpolate/one_dimension.py:147: UserWarning: Interpolation point out of data bounds encountered
  warnings.warn('Interpolation point out of data bounds encountered')
/home/zilnora/.conda/envs/MASTER_PROJECT_ENV/lib/python3.9/site-packages/metpy/interpolate/one_dimension.py:147: UserWarning: Interpolation point out of data bounds encountered
  warnings.warn('Interpolation point out of data bounds encountered')
/home/zilnora/.conda/envs/MASTER_PROJECT_ENV/lib/python3.9/site-packages/metpy/interpolate/one_dimension.py:147: UserWarning: Interpolation point out of data bounds encountered
  warnings.warn('Interpolation point out of data bounds encountered')
/home/zilnora/.conda/envs/MASTER_PROJECT_ENV/lib/python3.9/site-packages/metpy/interpolate/one_dimension.py:147: UserWarning: Interpolation point out of data bounds encountered
  warnings.warn('Interpolation point out of data bounds encountered')
/home/zilnora/.conda/envs/MASTER_PROJECT_ENV/lib/python3.9/site-packages/metpy/interpolate/one_dimension.py:147: UserWarning: Interpolation point out of data bounds encountered
  warnings.warn('Interpolation point out of data bounds encountered')
/home/zilnora/.conda/envs/MASTER_PROJECT_ENV/lib/python3.9/site-packages/metpy/interpolate/one_dimension.py:147: UserWarning: Interpolation point out of data bounds encountered
  warnings.warn('Interpolation point out of data bounds encountered')
/home/zilnora/.conda/envs/MASTER_PROJECT_ENV/lib/python3.9/site-packages/metpy/interpolate/one_dimension.py:147: UserWarning: Interpolation point out of data bounds encountered
  warnings.warn('Interpolation point out of data bounds encountered')
/home/zilnora/.conda/envs/MASTER_PROJECT_ENV/lib/python3.9/site-packages/metpy/interpolate/one_dimension.py:147: UserWarning: Interpolation point out of data bounds encountered
  warnings.warn('Interpolation point out of data bounds encountered')
/home/zilnora/.conda/envs/MASTER_PROJECT_ENV/lib/python3.9/site-packages/metpy/interpolate/one_dimension.py:147: UserWarning: Interpolation point out of data bounds encountered
  warnings.warn('Interpolation point out of data bounds encountered')
/home/zilnora/.conda/envs/MASTER_PROJECT_ENV/lib/python3.9/site-packages/metpy/interpolate/one_dimension.py:147: UserWarning: Interpolation point out of data bounds encountered
  warnings.warn('Interpolation point out of data bounds encountered')
/home/zilnora/.conda/envs/MASTER_PROJECT_ENV/lib/python3.9/site-packages/metpy/interpolate/one_dimension.py:147: UserWarning: Interpolation point out of data bounds encountered
  warnings.warn('Interpolation point out of data bounds encountered')
/home/zilnora/.conda/envs/MASTER_PROJECT_ENV/lib/python3.9/site-packages/metpy/interpolate/one_dimension.py:147: UserWarning: Interpolation point out of data bounds encountered
  warnings.warn('Interpolation point out of data bounds encountered')
/home/zilnora/.conda/envs/MASTER_PROJECT_ENV/lib/python3.9/site-packages/metpy/interpolate/one_dimension.py:147: UserWarning: Interpolation point out of data bounds encountered
  warnings.warn('Interpolation point out of data bounds encountered')
/home/zilnora/.conda/envs/MASTER_PROJECT_ENV/lib/python3.9/site-packages/metpy/interpolate/one_dimension.py:147: UserWarning: Interpolation point out of data bounds encountered
  warnings.warn('Interpolation point out of data bounds encountered')
/home/zilnora/.conda/envs/MASTER_PROJECT_ENV/lib/python3.9/site-packages/metpy/interpolate/one_dimension.py:147: UserWarning: Interpolation point out of data bounds encountered
  warnings.warn('Interpolation point out of data bounds encountered')
/home/zilnora/.conda/envs/MASTER_PROJECT_ENV/lib/python3.9/site-packages/metpy/interpolate/one_dimension.py:147: UserWarning: Interpolation point out of data bounds encountered
  warnings.warn('Interpolation point out of data bounds encountered')
/home/zilnora/.conda/envs/MASTER_PROJECT_ENV/lib/python3.9/site-packages/metpy/interpolate/one_dimension.py:147: UserWarning: Interpolation point out of data bounds encountered
  warnings.warn('Interpolation point out of data bounds encountered')
/home/zilnora/.conda/envs/MASTER_PROJECT_ENV/lib/python3.9/site-packages/metpy/interpolate/one_dimension.py:147: UserWarning: Interpolation point out of data bounds encountered
  warnings.warn('Interpolation point out of data bounds encountered')
/home/zilnora/.conda/envs/MASTER_PROJECT_ENV/lib/python3.9/site-packages/metpy/interpolate/one_dimension.py:147: UserWarning: Interpolation point out of data bounds encountered
  warnings.warn('Interpolation point out of data bounds encountered')
/home/zilnora/.conda/envs/MASTER_PROJECT_ENV/lib/python3.9/site-packages/metpy/interpolate/one_dimension.py:147: UserWarning: Interpolation point out of data bounds encountered
  warnings.warn('Interpolation point out of data bounds encountered')
/home/zilnora/.conda/envs/MASTER_PROJECT_ENV/lib/python3.9/site-packages/metpy/interpolate/one_dimension.py:147: UserWarning: Interpolation point out of data bounds encountered
  warnings.warn('Interpolation point out of data bounds encountered')
/home/zilnora/.conda/envs/MASTER_PROJECT_ENV/lib/python3.9/site-packages/metpy/interpolate/one_dimension.py:147: UserWarning: Interpolation point out of data bounds encountered
  warnings.warn('Interpolation point out of data bounds encountered')
/home/zilnora/.conda/envs/MASTER_PROJECT_ENV/lib/python3.9/site-packages/metpy/interpolate/one_dimension.py:147: UserWarning: Interpolation point out of data bounds encountered
  warnings.warn('Interpolation point out of data bounds encountered')
/home/zilnora/.conda/envs/MASTER_PROJECT_ENV/lib/python3.9/site-packages/metpy/interpolate/one_dimension.py:147: UserWarning: Interpolation point out of data bounds encountered
  warnings.warn('Interpolation point out of data bounds encountered')
/home/zilnora/.conda/envs/MASTER_PROJECT_ENV/lib/python3.9/site-packages/metpy/interpolate/one_dimension.py:147: UserWarning: Interpolation point out of data bounds encountered
  warnings.warn('Interpolation point out of data bounds encountered')
/home/zilnora/.conda/envs/MASTER_PROJECT_ENV/lib/python3.9/site-packages/metpy/interpolate/one_dimension.py:147: UserWarning: Interpolation point out of data bounds encountered
  warnings.warn('Interpolation point out of data bounds encountered')
/home/zilnora/.conda/envs/MASTER_PROJECT_ENV/lib/python3.9/site-packages/metpy/interpolate/one_dimension.py:147: UserWarning: Interpolation point out of data bounds encountered
  warnings.warn('Interpolation point out of data bounds encountered')
/home/zilnora/.conda/envs/MASTER_PROJECT_ENV/lib/python3.9/site-packages/metpy/interpolate/one_dimension.py:147: UserWarning: Interpolation point out of data bounds encountered
  warnings.warn('Interpolation point out of data bounds encountered')
/home/zilnora/.conda/envs/MASTER_PROJECT_ENV/lib/python3.9/site-packages/metpy/interpolate/one_dimension.py:147: UserWarning: Interpolation point out of data bounds encountered
  warnings.warn('Interpolation point out of data bounds encountered')
/home/zilnora/.conda/envs/MASTER_PROJECT_ENV/lib/python3.9/site-packages/metpy/interpolate/one_dimension.py:147: UserWarning: Interpolation point out of data bounds encountered
  warnings.warn('Interpolation point out of data bounds encountered')
/home/zilnora/.conda/envs/MASTER_PROJECT_ENV/lib/python3.9/site-packages/metpy/interpolate/one_dimension.py:147: UserWarning: Interpolation point out of data bounds encountered
  warnings.warn('Interpolation point out of data bounds encountered')
/home/zilnora/.conda/envs/MASTER_PROJECT_ENV/lib/python3.9/site-packages/metpy/interpolate/one_dimension.py:147: UserWarning: Interpolation point out of data bounds encountered
  warnings.warn('Interpolation point out of data bounds encountered')
/home/zilnora/.conda/envs/MASTER_PROJECT_ENV/lib/python3.9/site-packages/metpy/interpolate/one_dimension.py:147: UserWarning: Interpolation point out of data bounds encountered
  warnings.warn('Interpolation point out of data bounds encountered')
/home/zilnora/.conda/envs/MASTER_PROJECT_ENV/lib/python3.9/site-packages/metpy/interpolate/one_dimension.py:147: UserWarning: Interpolation point out of data bounds encountered
  warnings.warn('Interpolation point out of data bounds encountered')
/home/zilnora/.conda/envs/MASTER_PROJECT_ENV/lib/python3.9/site-packages/metpy/interpolate/one_dimension.py:147: UserWarning: Interpolation point out of data bounds encountered
  warnings.warn('Interpolation point out of data bounds encountered')
/home/zilnora/.conda/envs/MASTER_PROJECT_ENV/lib/python3.9/site-packages/metpy/interpolate/one_dimension.py:147: UserWarning: Interpolation point out of data bounds encountered
  warnings.warn('Interpolation point out of data bounds encountered')
/home/zilnora/.conda/envs/MASTER_PROJECT_ENV/lib/python3.9/site-packages/metpy/interpolate/one_dimension.py:147: UserWarning: Interpolation point out of data bounds encountered
  warnings.warn('Interpolation point out of data bounds encountered')
/home/zilnora/.conda/envs/MASTER_PROJECT_ENV/lib/python3.9/site-packages/metpy/interpolate/one_dimension.py:147: UserWarning: Interpolation point out of data bounds encountered
  warnings.warn('Interpolation point out of data bounds encountered')
/home/zilnora/.conda/envs/MASTER_PROJECT_ENV/lib/python3.9/site-packages/metpy/interpolate/one_dimension.py:147: UserWarning: Interpolation point out of data bounds encountered
  warnings.warn('Interpolation point out of data bounds encountered')
/home/zilnora/.conda/envs/MASTER_PROJECT_ENV/lib/python3.9/site-packages/metpy/interpolate/one_dimension.py:147: UserWarning: Interpolation point out of data bounds encountered
  warnings.warn('Interpolation point out of data bounds encountered')
/home/zilnora/.conda/envs/MASTER_PROJECT_ENV/lib/python3.9/site-packages/metpy/interpolate/one_dimension.py:147: UserWarning: Interpolation point out of data bounds encountered
  warnings.warn('Interpolation point out of data bounds encountered')
/home/zilnora/.conda/envs/MASTER_PROJECT_ENV/lib/python3.9/site-packages/metpy/interpolate/one_dimension.py:147: UserWarning: Interpolation point out of data bounds encountered
  warnings.warn('Interpolation point out of data bounds encountered')
/home/zilnora/.conda/envs/MASTER_PROJECT_ENV/lib/python3.9/site-packages/metpy/interpolate/one_dimension.py:147: UserWarning: Interpolation point out of data bounds encountered
  warnings.warn('Interpolation point out of data bounds encountered')
/home/zilnora/.conda/envs/MASTER_PROJECT_ENV/lib/python3.9/site-packages/metpy/interpolate/one_dimension.py:147: UserWarning: Interpolation point out of data bounds encountered
  warnings.warn('Interpolation point out of data bounds encountered')
/home/zilnora/.conda/envs/MASTER_PROJECT_ENV/lib/python3.9/site-packages/metpy/interpolate/one_dimension.py:147: UserWarning: Interpolation point out of data bounds encountered
  warnings.warn('Interpolation point out of data bounds encountered')
Traceback (most recent call last):
  File "/net/ch4/atmcirc/zilnora/era5_midwinter/code/EKE_calculations/interpolate_EKE_to_TH.py", line 23, in <module>
    df2=xr.open_dataset(args.file2)
  File "/home/zilnora/.conda/envs/MASTER_PROJECT_ENV/lib/python3.9/site-packages/xarray/backends/api.py", line 479, in open_dataset
    engine = plugins.guess_engine(filename_or_obj)
  File "/home/zilnora/.conda/envs/MASTER_PROJECT_ENV/lib/python3.9/site-packages/xarray/backends/plugins.py", line 148, in guess_engine
    raise ValueError(error_msg)
ValueError: did not find a match in any of xarray's currently installed IO backends ['netcdf4', 'h5netcdf', 'scipy', 'cfgrib', 'zarr']. Consider explicitly selecting one of the installed engines via the ``engine`` parameter, or installing additional IO dependencies, see:
https://docs.xarray.dev/en/stable/getting-started-guide/installing.html
https://docs.xarray.dev/en/stable/user-guide/io.html
Traceback (most recent call last):
  File "/net/ch4/atmcirc/zilnora/era5_midwinter/code/EKE_calculations/interpolate_EKE_to_TH.py", line 23, in <module>
    df2=xr.open_dataset(args.file2)
  File "/home/zilnora/.conda/envs/MASTER_PROJECT_ENV/lib/python3.9/site-packages/xarray/backends/api.py", line 479, in open_dataset
    engine = plugins.guess_engine(filename_or_obj)
  File "/home/zilnora/.conda/envs/MASTER_PROJECT_ENV/lib/python3.9/site-packages/xarray/backends/plugins.py", line 148, in guess_engine
    raise ValueError(error_msg)
ValueError: did not find a match in any of xarray's currently installed IO backends ['netcdf4', 'h5netcdf', 'scipy', 'cfgrib', 'zarr']. Consider explicitly selecting one of the installed engines via the ``engine`` parameter, or installing additional IO dependencies, see:
https://docs.xarray.dev/en/stable/getting-started-guide/installing.html
https://docs.xarray.dev/en/stable/user-guide/io.html
Traceback (most recent call last):
  File "/net/ch4/atmcirc/zilnora/era5_midwinter/code/EKE_calculations/interpolate_EKE_to_TH.py", line 23, in <module>
    df2=xr.open_dataset(args.file2)
  File "/home/zilnora/.conda/envs/MASTER_PROJECT_ENV/lib/python3.9/site-packages/xarray/backends/api.py", line 479, in open_dataset
    engine = plugins.guess_engine(filename_or_obj)
  File "/home/zilnora/.conda/envs/MASTER_PROJECT_ENV/lib/python3.9/site-packages/xarray/backends/plugins.py", line 148, in guess_engine
    raise ValueError(error_msg)
ValueError: did not find a match in any of xarray's currently installed IO backends ['netcdf4', 'h5netcdf', 'scipy', 'cfgrib', 'zarr']. Consider explicitly selecting one of the installed engines via the ``engine`` parameter, or installing additional IO dependencies, see:
https://docs.xarray.dev/en/stable/getting-started-guide/installing.html
https://docs.xarray.dev/en/stable/user-guide/io.html
Traceback (most recent call last):
  File "/net/ch4/atmcirc/zilnora/era5_midwinter/code/EKE_calculations/interpolate_EKE_to_TH.py", line 23, in <module>
    df2=xr.open_dataset(args.file2)
  File "/home/zilnora/.conda/envs/MASTER_PROJECT_ENV/lib/python3.9/site-packages/xarray/backends/api.py", line 479, in open_dataset
    engine = plugins.guess_engine(filename_or_obj)
  File "/home/zilnora/.conda/envs/MASTER_PROJECT_ENV/lib/python3.9/site-packages/xarray/backends/plugins.py", line 148, in guess_engine
    raise ValueError(error_msg)
ValueError: did not find a match in any of xarray's currently installed IO backends ['netcdf4', 'h5netcdf', 'scipy', 'cfgrib', 'zarr']. Consider explicitly selecting one of the installed engines via the ``engine`` parameter, or installing additional IO dependencies, see:
https://docs.xarray.dev/en/stable/getting-started-guide/installing.html
https://docs.xarray.dev/en/stable/user-guide/io.html
Traceback (most recent call last):
  File "/net/ch4/atmcirc/zilnora/era5_midwinter/code/EKE_calculations/interpolate_EKE_to_TH.py", line 23, in <module>
    df2=xr.open_dataset(args.file2)
  File "/home/zilnora/.conda/envs/MASTER_PROJECT_ENV/lib/python3.9/site-packages/xarray/backends/api.py", line 479, in open_dataset
    engine = plugins.guess_engine(filename_or_obj)
  File "/home/zilnora/.conda/envs/MASTER_PROJECT_ENV/lib/python3.9/site-packages/xarray/backends/plugins.py", line 148, in guess_engine
    raise ValueError(error_msg)
ValueError: did not find a match in any of xarray's currently installed IO backends ['netcdf4', 'h5netcdf', 'scipy', 'cfgrib', 'zarr']. Consider explicitly selecting one of the installed engines via the ``engine`` parameter, or installing additional IO dependencies, see:
https://docs.xarray.dev/en/stable/getting-started-guide/installing.html
https://docs.xarray.dev/en/stable/user-guide/io.html
